Traceback (most recent call last):
  File "/home/henryj/deepfake/venv/lib/python3.10/urllib/request.py", line 1348, in do_open
    h.request(req.get_method(), req.selector, req.data, headers,
  File "/home/henryj/deepfake/venv/lib/python3.10/http/client.py", line 1283, in request
    self._send_request(method, url, body, headers, encode_chunked)
  File "/home/henryj/deepfake/venv/lib/python3.10/http/client.py", line 1329, in _send_request
    self.endheaders(body, encode_chunked=encode_chunked)
  File "/home/henryj/deepfake/venv/lib/python3.10/http/client.py", line 1278, in endheaders
    self._send_output(message_body, encode_chunked=encode_chunked)
  File "/home/henryj/deepfake/venv/lib/python3.10/http/client.py", line 1038, in _send_output
    self.send(msg)
  File "/home/henryj/deepfake/venv/lib/python3.10/http/client.py", line 976, in send
    self.connect()
  File "/home/henryj/deepfake/venv/lib/python3.10/http/client.py", line 1448, in connect
    super().connect()
  File "/home/henryj/deepfake/venv/lib/python3.10/http/client.py", line 942, in connect
    self.sock = self._create_connection(
  File "/home/henryj/deepfake/venv/lib/python3.10/socket.py", line 845, in create_connection
    raise err
  File "/home/henryj/deepfake/venv/lib/python3.10/socket.py", line 833, in create_connection
    sock.connect(sa)
OSError: [Errno 101] Network is unreachable

During handling of the above exception, another exception occurred:

Traceback (most recent call last):
  File "/home/henryj/deepfake/training_data/scripts/transcribe_wavs_to_metadata.py", line 13, in <module>
    model = whisper.load_model("small.en")
  File "/home/henryj/deepfake/venv/lib/python3.10/site-packages/whisper/__init__.py", line 133, in load_model
    checkpoint_file = _download(_MODELS[name], download_root, in_memory)
  File "/home/henryj/deepfake/venv/lib/python3.10/site-packages/whisper/__init__.py", line 69, in _download
    with urllib.request.urlopen(url) as source, open(download_target, "wb") as output:
  File "/home/henryj/deepfake/venv/lib/python3.10/urllib/request.py", line 216, in urlopen
    return opener.open(url, data, timeout)
  File "/home/henryj/deepfake/venv/lib/python3.10/urllib/request.py", line 519, in open
    response = self._open(req, data)
  File "/home/henryj/deepfake/venv/lib/python3.10/urllib/request.py", line 536, in _open
    result = self._call_chain(self.handle_open, protocol, protocol +
  File "/home/henryj/deepfake/venv/lib/python3.10/urllib/request.py", line 496, in _call_chain
    result = func(*args)
  File "/home/henryj/deepfake/venv/lib/python3.10/urllib/request.py", line 1391, in https_open
    return self.do_open(http.client.HTTPSConnection, req,
  File "/home/henryj/deepfake/venv/lib/python3.10/urllib/request.py", line 1351, in do_open
    raise URLError(err)
urllib.error.URLError: <urlopen error [Errno 101] Network is unreachable>
