 > Training Environment:
 | > Backend: Torch
 | > Mixed precision: False
 | > Precision: float32
 | > Current device: 0
 | > Num. of GPUs: 1
 | > Num. of CPUs: 48
 | > Num. of Torch Threads: 1
 | > Torch seed: 1
 | > Torch CUDNN: True
 | > Torch CUDNN deterministic: False
 | > Torch CUDNN benchmark: False
 | > Torch TF32 MatMul: False
 > Start Tensorboard: tensorboard --logdir=/home/henryj/deepfake/training_data/scripts/run/training/GPT_XTTS_v2.0_LJSpeech_FT-April-27-2024_12+54PM-f832550

 > Model has 518442047 parameters
Traceback (most recent call last):
  File "/home/henryj/deepfake/venv/lib/python3.10/site-packages/urllib3/connection.py", line 198, in _new_conn
    sock = connection.create_connection(
  File "/home/henryj/deepfake/venv/lib/python3.10/site-packages/urllib3/util/connection.py", line 85, in create_connection
    raise err
  File "/home/henryj/deepfake/venv/lib/python3.10/site-packages/urllib3/util/connection.py", line 73, in create_connection
    sock.connect(sa)
TimeoutError: timed out

The above exception was the direct cause of the following exception:

Traceback (most recent call last):
  File "/home/henryj/deepfake/venv/lib/python3.10/site-packages/urllib3/connectionpool.py", line 793, in urlopen
    response = self._make_request(
  File "/home/henryj/deepfake/venv/lib/python3.10/site-packages/urllib3/connectionpool.py", line 491, in _make_request
    raise new_e
  File "/home/henryj/deepfake/venv/lib/python3.10/site-packages/urllib3/connectionpool.py", line 467, in _make_request
    self._validate_conn(conn)
  File "/home/henryj/deepfake/venv/lib/python3.10/site-packages/urllib3/connectionpool.py", line 1099, in _validate_conn
    conn.connect()
  File "/home/henryj/deepfake/venv/lib/python3.10/site-packages/urllib3/connection.py", line 616, in connect
    self.sock = sock = self._new_conn()
  File "/home/henryj/deepfake/venv/lib/python3.10/site-packages/urllib3/connection.py", line 207, in _new_conn
    raise ConnectTimeoutError(
urllib3.exceptions.ConnectTimeoutError: (<urllib3.connection.HTTPSConnection object at 0x7fd3e5b90d00>, 'Connection to coqui.gateway.scarf.sh timed out. (connect timeout=5)')

The above exception was the direct cause of the following exception:

Traceback (most recent call last):
  File "/home/henryj/deepfake/venv/lib/python3.10/site-packages/requests/adapters.py", line 486, in send
    resp = conn.urlopen(
  File "/home/henryj/deepfake/venv/lib/python3.10/site-packages/urllib3/connectionpool.py", line 847, in urlopen
    retries = retries.increment(
  File "/home/henryj/deepfake/venv/lib/python3.10/site-packages/urllib3/util/retry.py", line 515, in increment
    raise MaxRetryError(_pool, url, reason) from reason  # type: ignore[arg-type]
urllib3.exceptions.MaxRetryError: HTTPSConnectionPool(host='coqui.gateway.scarf.sh', port=443): Max retries exceeded with url: /trainer/training_run (Caused by ConnectTimeoutError(<urllib3.connection.HTTPSConnection object at 0x7fd3e5b90d00>, 'Connection to coqui.gateway.scarf.sh timed out. (connect timeout=5)'))

During handling of the above exception, another exception occurred:

Traceback (most recent call last):
  File "/home/henryj/deepfake/training_data/scripts/train.py", line 200, in <module>
    main()
  File "/home/henryj/deepfake/training_data/scripts/train.py", line 182, in main
    trainer = Trainer(
  File "/home/henryj/deepfake/venv/lib/python3.10/site-packages/trainer/trainer.py", line 583, in __init__
    ping_training_run()
  File "/home/henryj/deepfake/venv/lib/python3.10/site-packages/trainer/analytics.py", line 12, in ping_training_run
    _ = requests.get(URL, timeout=5)
  File "/home/henryj/deepfake/venv/lib/python3.10/site-packages/requests/api.py", line 73, in get
    return request("get", url, params=params, **kwargs)
  File "/home/henryj/deepfake/venv/lib/python3.10/site-packages/requests/api.py", line 59, in request
    return session.request(method=method, url=url, **kwargs)
  File "/home/henryj/deepfake/venv/lib/python3.10/site-packages/requests/sessions.py", line 589, in request
    resp = self.send(prep, **send_kwargs)
  File "/home/henryj/deepfake/venv/lib/python3.10/site-packages/requests/sessions.py", line 703, in send
    r = adapter.send(request, **kwargs)
  File "/home/henryj/deepfake/venv/lib/python3.10/site-packages/requests/adapters.py", line 507, in send
    raise ConnectTimeout(e, request=request)
requests.exceptions.ConnectTimeout: HTTPSConnectionPool(host='coqui.gateway.scarf.sh', port=443): Max retries exceeded with url: /trainer/training_run (Caused by ConnectTimeoutError(<urllib3.connection.HTTPSConnection object at 0x7fd3e5b90d00>, 'Connection to coqui.gateway.scarf.sh timed out. (connect timeout=5)'))
